2014-08-04 14:57:23,621 [ERROR] django.request: Internal Server Error: /token/
Traceback (most recent call last):
  File "/usr/local/lib/python2.7/dist-packages/django/core/handlers/base.py", line 112, in get_response
    response = wrapped_callback(request, *callback_args, **callback_kwargs)
  File "/usr/local/lib/python2.7/dist-packages/django/views/generic/base.py", line 69, in view
    return self.dispatch(request, *args, **kwargs)
  File "/usr/local/lib/python2.7/dist-packages/django/views/decorators/csrf.py", line 57, in wrapped_view
    return view_func(*args, **kwargs)
  File "/usr/local/lib/python2.7/dist-packages/rest_framework/views.py", line 400, in dispatch
    response = self.handle_exception(exc)
  File "/usr/local/lib/python2.7/dist-packages/rest_framework/views.py", line 397, in dispatch
    response = handler(request, *args, **kwargs)
  File "/usr/local/lib/python2.7/dist-packages/django/utils/decorators.py", line 29, in _wrapper
    return bound_func(*args, **kwargs)
  File "/usr/local/lib/python2.7/dist-packages/django/utils/decorators.py", line 99, in _wrapped_view
    response = view_func(request, *args, **kwargs)
  File "/usr/local/lib/python2.7/dist-packages/django/utils/decorators.py", line 25, in bound_func
    return func(self, *args2, **kwargs2)
  File "./happy365/views.py", line 206, in post
    token.save()
  File "/usr/local/lib/python2.7/dist-packages/django/db/models/base.py", line 545, in save
    force_update=force_update, update_fields=update_fields)
  File "/usr/local/lib/python2.7/dist-packages/django/db/models/base.py", line 573, in save_base
    updated = self._save_table(raw, cls, force_insert, force_update, using, update_fields)
  File "/usr/local/lib/python2.7/dist-packages/django/db/models/base.py", line 654, in _save_table
    result = self._do_insert(cls._base_manager, using, fields, update_pk, raw)
  File "/usr/local/lib/python2.7/dist-packages/django/db/models/base.py", line 687, in _do_insert
    using=using, raw=raw)
  File "/usr/local/lib/python2.7/dist-packages/django/db/models/manager.py", line 232, in _insert
    return insert_query(self.model, objs, fields, **kwargs)
  File "/usr/local/lib/python2.7/dist-packages/django/db/models/query.py", line 1514, in insert_query
    return query.get_compiler(using=using).execute_sql(return_id)
  File "/usr/local/lib/python2.7/dist-packages/django/db/models/sql/compiler.py", line 902, in execute_sql
    for sql, params in self.as_sql():
  File "/usr/local/lib/python2.7/dist-packages/django/db/models/sql/compiler.py", line 860, in as_sql
    for obj in self.query.objs
  File "/usr/local/lib/python2.7/dist-packages/django/db/models/fields/__init__.py", line 350, in get_db_prep_save
    prepared=False)
  File "/usr/local/lib/python2.7/dist-packages/django/db/models/fields/__init__.py", line 342, in get_db_prep_value
    value = self.get_prep_value(value)
  File "/usr/local/lib/python2.7/dist-packages/django/db/models/fields/__init__.py", line 1079, in get_prep_value
    return int(value)
ValueError: invalid literal for int() with base 10: '{"access_token":"2.00_gGqzB0XcX3gc486e711e72GDoKB","remind_in":"129756","expires_in":129756,"uid":"1829908071"}'
2014-08-04 15:04:04,298 [ERROR] django.request: Internal Server Error: /token/
Traceback (most recent call last):
  File "/usr/local/lib/python2.7/dist-packages/django/core/handlers/base.py", line 112, in get_response
    response = wrapped_callback(request, *callback_args, **callback_kwargs)
  File "/usr/local/lib/python2.7/dist-packages/django/views/generic/base.py", line 69, in view
    return self.dispatch(request, *args, **kwargs)
  File "/usr/local/lib/python2.7/dist-packages/django/views/decorators/csrf.py", line 57, in wrapped_view
    return view_func(*args, **kwargs)
  File "/usr/local/lib/python2.7/dist-packages/rest_framework/views.py", line 400, in dispatch
    response = self.handle_exception(exc)
  File "/usr/local/lib/python2.7/dist-packages/rest_framework/views.py", line 397, in dispatch
    response = handler(request, *args, **kwargs)
  File "/usr/local/lib/python2.7/dist-packages/django/utils/decorators.py", line 29, in _wrapper
    return bound_func(*args, **kwargs)
  File "/usr/local/lib/python2.7/dist-packages/django/utils/decorators.py", line 99, in _wrapped_view
    response = view_func(request, *args, **kwargs)
  File "/usr/local/lib/python2.7/dist-packages/django/utils/decorators.py", line 25, in bound_func
    return func(self, *args2, **kwargs2)
  File "./happy365/views.py", line 206, in post
    token.save()
  File "/usr/local/lib/python2.7/dist-packages/django/db/models/base.py", line 545, in save
    force_update=force_update, update_fields=update_fields)
  File "/usr/local/lib/python2.7/dist-packages/django/db/models/base.py", line 573, in save_base
    updated = self._save_table(raw, cls, force_insert, force_update, using, update_fields)
  File "/usr/local/lib/python2.7/dist-packages/django/db/models/base.py", line 654, in _save_table
    result = self._do_insert(cls._base_manager, using, fields, update_pk, raw)
  File "/usr/local/lib/python2.7/dist-packages/django/db/models/base.py", line 687, in _do_insert
    using=using, raw=raw)
  File "/usr/local/lib/python2.7/dist-packages/django/db/models/manager.py", line 232, in _insert
    return insert_query(self.model, objs, fields, **kwargs)
  File "/usr/local/lib/python2.7/dist-packages/django/db/models/query.py", line 1514, in insert_query
    return query.get_compiler(using=using).execute_sql(return_id)
  File "/usr/local/lib/python2.7/dist-packages/django/db/models/sql/compiler.py", line 902, in execute_sql
    for sql, params in self.as_sql():
  File "/usr/local/lib/python2.7/dist-packages/django/db/models/sql/compiler.py", line 860, in as_sql
    for obj in self.query.objs
  File "/usr/local/lib/python2.7/dist-packages/django/db/models/fields/__init__.py", line 350, in get_db_prep_save
    prepared=False)
  File "/usr/local/lib/python2.7/dist-packages/django/db/models/fields/__init__.py", line 342, in get_db_prep_value
    value = self.get_prep_value(value)
  File "/usr/local/lib/python2.7/dist-packages/django/db/models/fields/__init__.py", line 1079, in get_prep_value
    return int(value)
ValueError: invalid literal for int() with base 10: '{"access_token":"2.00_gGqzB0XcX3g429bad4c66W68PaE","remind_in":"129356","expires_in":129356,"uid":"1829908071"}'
2014-08-04 15:08:10,673 [ERROR] django.request: Internal Server Error: /token/
Traceback (most recent call last):
  File "/usr/local/lib/python2.7/dist-packages/django/core/handlers/base.py", line 112, in get_response
    response = wrapped_callback(request, *callback_args, **callback_kwargs)
  File "/usr/local/lib/python2.7/dist-packages/django/views/generic/base.py", line 69, in view
    return self.dispatch(request, *args, **kwargs)
  File "/usr/local/lib/python2.7/dist-packages/django/views/decorators/csrf.py", line 57, in wrapped_view
    return view_func(*args, **kwargs)
  File "/usr/local/lib/python2.7/dist-packages/rest_framework/views.py", line 400, in dispatch
    response = self.handle_exception(exc)
  File "/usr/local/lib/python2.7/dist-packages/rest_framework/views.py", line 397, in dispatch
    response = handler(request, *args, **kwargs)
  File "/usr/local/lib/python2.7/dist-packages/django/utils/decorators.py", line 29, in _wrapper
    return bound_func(*args, **kwargs)
  File "/usr/local/lib/python2.7/dist-packages/django/utils/decorators.py", line 99, in _wrapped_view
    response = view_func(request, *args, **kwargs)
  File "/usr/local/lib/python2.7/dist-packages/django/utils/decorators.py", line 25, in bound_func
    return func(self, *args2, **kwargs2)
  File "./happy365/views.py", line 184, in post
    loger.info(data)
NameError: global name 'loger' is not defined
2014-08-04 15:15:40,631 [ERROR] django.request: Internal Server Error: /token/
Traceback (most recent call last):
  File "/usr/local/lib/python2.7/dist-packages/django/core/handlers/base.py", line 112, in get_response
    response = wrapped_callback(request, *callback_args, **callback_kwargs)
  File "/usr/local/lib/python2.7/dist-packages/django/views/generic/base.py", line 69, in view
    return self.dispatch(request, *args, **kwargs)
  File "/usr/local/lib/python2.7/dist-packages/django/views/decorators/csrf.py", line 57, in wrapped_view
    return view_func(*args, **kwargs)
  File "/usr/local/lib/python2.7/dist-packages/rest_framework/views.py", line 400, in dispatch
    response = self.handle_exception(exc)
  File "/usr/local/lib/python2.7/dist-packages/rest_framework/views.py", line 397, in dispatch
    response = handler(request, *args, **kwargs)
  File "/usr/local/lib/python2.7/dist-packages/django/utils/decorators.py", line 29, in _wrapper
    return bound_func(*args, **kwargs)
  File "/usr/local/lib/python2.7/dist-packages/django/utils/decorators.py", line 99, in _wrapped_view
    response = view_func(request, *args, **kwargs)
  File "/usr/local/lib/python2.7/dist-packages/django/utils/decorators.py", line 25, in bound_func
    return func(self, *args2, **kwargs2)
  File "./happy365/views.py", line 207, in post
    token.save()
  File "/usr/local/lib/python2.7/dist-packages/django/db/models/base.py", line 545, in save
    force_update=force_update, update_fields=update_fields)
  File "/usr/local/lib/python2.7/dist-packages/django/db/models/base.py", line 573, in save_base
    updated = self._save_table(raw, cls, force_insert, force_update, using, update_fields)
  File "/usr/local/lib/python2.7/dist-packages/django/db/models/base.py", line 654, in _save_table
    result = self._do_insert(cls._base_manager, using, fields, update_pk, raw)
  File "/usr/local/lib/python2.7/dist-packages/django/db/models/base.py", line 687, in _do_insert
    using=using, raw=raw)
  File "/usr/local/lib/python2.7/dist-packages/django/db/models/manager.py", line 232, in _insert
    return insert_query(self.model, objs, fields, **kwargs)
  File "/usr/local/lib/python2.7/dist-packages/django/db/models/query.py", line 1514, in insert_query
    return query.get_compiler(using=using).execute_sql(return_id)
  File "/usr/local/lib/python2.7/dist-packages/django/db/models/sql/compiler.py", line 902, in execute_sql
    for sql, params in self.as_sql():
  File "/usr/local/lib/python2.7/dist-packages/django/db/models/sql/compiler.py", line 860, in as_sql
    for obj in self.query.objs
  File "/usr/local/lib/python2.7/dist-packages/django/db/models/fields/__init__.py", line 350, in get_db_prep_save
    prepared=False)
  File "/usr/local/lib/python2.7/dist-packages/django/db/models/fields/__init__.py", line 342, in get_db_prep_value
    value = self.get_prep_value(value)
  File "/usr/local/lib/python2.7/dist-packages/django/db/models/fields/__init__.py", line 1079, in get_prep_value
    return int(value)
ValueError: invalid literal for int() with base 10: '{"access_token":"2.00_gGqzB0XcX3ga2cb7addeemMTeAD","remind_in":"128659","expires_in":128659,"uid":"1829908071"}'
2014-08-04 15:19:25,383 [ERROR] django.request: Internal Server Error: /signin/
Traceback (most recent call last):
  File "/usr/local/lib/python2.7/dist-packages/django/core/handlers/base.py", line 112, in get_response
    response = wrapped_callback(request, *callback_args, **callback_kwargs)
  File "/usr/local/lib/python2.7/dist-packages/django/views/generic/base.py", line 69, in view
    return self.dispatch(request, *args, **kwargs)
  File "/usr/local/lib/python2.7/dist-packages/django/views/decorators/csrf.py", line 57, in wrapped_view
    return view_func(*args, **kwargs)
  File "/usr/local/lib/python2.7/dist-packages/rest_framework/views.py", line 400, in dispatch
    response = self.handle_exception(exc)
  File "/usr/local/lib/python2.7/dist-packages/rest_framework/views.py", line 397, in dispatch
    response = handler(request, *args, **kwargs)
  File "/usr/local/lib/python2.7/dist-packages/django/utils/decorators.py", line 29, in _wrapper
    return bound_func(*args, **kwargs)
  File "/usr/local/lib/python2.7/dist-packages/django/utils/decorators.py", line 99, in _wrapped_view
    response = view_func(request, *args, **kwargs)
  File "/usr/local/lib/python2.7/dist-packages/django/utils/decorators.py", line 25, in bound_func
    return func(self, *args2, **kwargs2)
  File "./happy365/views.py", line 118, in post
    user = authenticate(username=username, password=password)
  File "/usr/local/lib/python2.7/dist-packages/django/contrib/auth/__init__.py", line 49, in authenticate
    user = backend.authenticate(**credentials)
  File "/usr/local/lib/python2.7/dist-packages/django/contrib/auth/backends.py", line 16, in authenticate
    user = UserModel._default_manager.get_by_natural_key(username)
  File "/usr/local/lib/python2.7/dist-packages/django/contrib/auth/models.py", line 167, in get_by_natural_key
    return self.get(**{self.model.USERNAME_FIELD: username})
  File "/usr/local/lib/python2.7/dist-packages/django/db/models/manager.py", line 151, in get
    return self.get_queryset().get(*args, **kwargs)
  File "/usr/local/lib/python2.7/dist-packages/django/db/models/query.py", line 304, in get
    num = len(clone)
  File "/usr/local/lib/python2.7/dist-packages/django/db/models/query.py", line 77, in __len__
    self._fetch_all()
  File "/usr/local/lib/python2.7/dist-packages/django/db/models/query.py", line 857, in _fetch_all
    self._result_cache = list(self.iterator())
  File "/usr/local/lib/python2.7/dist-packages/django/db/models/query.py", line 220, in iterator
    for row in compiler.results_iter():
  File "/usr/local/lib/python2.7/dist-packages/django/db/models/sql/compiler.py", line 713, in results_iter
    for rows in self.execute_sql(MULTI):
  File "/usr/local/lib/python2.7/dist-packages/django/db/models/sql/compiler.py", line 786, in execute_sql
    cursor.execute(sql, params)
  File "/usr/local/lib/python2.7/dist-packages/django/db/backends/util.py", line 69, in execute
    return super(CursorDebugWrapper, self).execute(sql, params)
  File "/usr/local/lib/python2.7/dist-packages/django/db/backends/util.py", line 53, in execute
    return self.cursor.execute(sql, params)
  File "/usr/local/lib/python2.7/dist-packages/django/db/utils.py", line 99, in __exit__
    six.reraise(dj_exc_type, dj_exc_value, traceback)
  File "/usr/local/lib/python2.7/dist-packages/django/db/backends/util.py", line 53, in execute
    return self.cursor.execute(sql, params)
  File "/usr/local/lib/python2.7/dist-packages/django/db/backends/mysql/base.py", line 124, in execute
    return self.cursor.execute(query, args)
  File "build/bdist.linux-x86_64/egg/MySQLdb/cursors.py", line 205, in execute
    self.errorhandler(self, exc, value)
  File "build/bdist.linux-x86_64/egg/MySQLdb/connections.py", line 36, in defaulterrorhandler
    raise errorclass, errorvalue
OperationalError: (1267, "Illegal mix of collations (latin1_swedish_ci,IMPLICIT) and (utf8_general_ci,COERCIBLE) for operation '='")
2014-08-04 15:19:26,962 [ERROR] django.request: Internal Server Error: /signin/
Traceback (most recent call last):
  File "/usr/local/lib/python2.7/dist-packages/django/core/handlers/base.py", line 112, in get_response
    response = wrapped_callback(request, *callback_args, **callback_kwargs)
  File "/usr/local/lib/python2.7/dist-packages/django/views/generic/base.py", line 69, in view
    return self.dispatch(request, *args, **kwargs)
  File "/usr/local/lib/python2.7/dist-packages/django/views/decorators/csrf.py", line 57, in wrapped_view
    return view_func(*args, **kwargs)
  File "/usr/local/lib/python2.7/dist-packages/rest_framework/views.py", line 400, in dispatch
    response = self.handle_exception(exc)
  File "/usr/local/lib/python2.7/dist-packages/rest_framework/views.py", line 397, in dispatch
    response = handler(request, *args, **kwargs)
  File "/usr/local/lib/python2.7/dist-packages/django/utils/decorators.py", line 29, in _wrapper
    return bound_func(*args, **kwargs)
  File "/usr/local/lib/python2.7/dist-packages/django/utils/decorators.py", line 99, in _wrapped_view
    response = view_func(request, *args, **kwargs)
  File "/usr/local/lib/python2.7/dist-packages/django/utils/decorators.py", line 25, in bound_func
    return func(self, *args2, **kwargs2)
  File "./happy365/views.py", line 118, in post
    user = authenticate(username=username, password=password)
  File "/usr/local/lib/python2.7/dist-packages/django/contrib/auth/__init__.py", line 49, in authenticate
    user = backend.authenticate(**credentials)
  File "/usr/local/lib/python2.7/dist-packages/django/contrib/auth/backends.py", line 16, in authenticate
    user = UserModel._default_manager.get_by_natural_key(username)
  File "/usr/local/lib/python2.7/dist-packages/django/contrib/auth/models.py", line 167, in get_by_natural_key
    return self.get(**{self.model.USERNAME_FIELD: username})
  File "/usr/local/lib/python2.7/dist-packages/django/db/models/manager.py", line 151, in get
    return self.get_queryset().get(*args, **kwargs)
  File "/usr/local/lib/python2.7/dist-packages/django/db/models/query.py", line 304, in get
    num = len(clone)
  File "/usr/local/lib/python2.7/dist-packages/django/db/models/query.py", line 77, in __len__
    self._fetch_all()
  File "/usr/local/lib/python2.7/dist-packages/django/db/models/query.py", line 857, in _fetch_all
    self._result_cache = list(self.iterator())
  File "/usr/local/lib/python2.7/dist-packages/django/db/models/query.py", line 220, in iterator
    for row in compiler.results_iter():
  File "/usr/local/lib/python2.7/dist-packages/django/db/models/sql/compiler.py", line 713, in results_iter
    for rows in self.execute_sql(MULTI):
  File "/usr/local/lib/python2.7/dist-packages/django/db/models/sql/compiler.py", line 786, in execute_sql
    cursor.execute(sql, params)
  File "/usr/local/lib/python2.7/dist-packages/django/db/backends/util.py", line 69, in execute
    return super(CursorDebugWrapper, self).execute(sql, params)
  File "/usr/local/lib/python2.7/dist-packages/django/db/backends/util.py", line 53, in execute
    return self.cursor.execute(sql, params)
  File "/usr/local/lib/python2.7/dist-packages/django/db/utils.py", line 99, in __exit__
    six.reraise(dj_exc_type, dj_exc_value, traceback)
  File "/usr/local/lib/python2.7/dist-packages/django/db/backends/util.py", line 53, in execute
    return self.cursor.execute(sql, params)
  File "/usr/local/lib/python2.7/dist-packages/django/db/backends/mysql/base.py", line 124, in execute
    return self.cursor.execute(query, args)
  File "build/bdist.linux-x86_64/egg/MySQLdb/cursors.py", line 205, in execute
    self.errorhandler(self, exc, value)
  File "build/bdist.linux-x86_64/egg/MySQLdb/connections.py", line 36, in defaulterrorhandler
    raise errorclass, errorvalue
OperationalError: (1267, "Illegal mix of collations (latin1_swedish_ci,IMPLICIT) and (utf8_general_ci,COERCIBLE) for operation '='")
2014-08-04 15:19:28,693 [ERROR] django.request: Internal Server Error: /signin/
Traceback (most recent call last):
  File "/usr/local/lib/python2.7/dist-packages/django/core/handlers/base.py", line 112, in get_response
    response = wrapped_callback(request, *callback_args, **callback_kwargs)
  File "/usr/local/lib/python2.7/dist-packages/django/views/generic/base.py", line 69, in view
    return self.dispatch(request, *args, **kwargs)
  File "/usr/local/lib/python2.7/dist-packages/django/views/decorators/csrf.py", line 57, in wrapped_view
    return view_func(*args, **kwargs)
  File "/usr/local/lib/python2.7/dist-packages/rest_framework/views.py", line 400, in dispatch
    response = self.handle_exception(exc)
  File "/usr/local/lib/python2.7/dist-packages/rest_framework/views.py", line 397, in dispatch
    response = handler(request, *args, **kwargs)
  File "/usr/local/lib/python2.7/dist-packages/django/utils/decorators.py", line 29, in _wrapper
    return bound_func(*args, **kwargs)
  File "/usr/local/lib/python2.7/dist-packages/django/utils/decorators.py", line 99, in _wrapped_view
    response = view_func(request, *args, **kwargs)
  File "/usr/local/lib/python2.7/dist-packages/django/utils/decorators.py", line 25, in bound_func
    return func(self, *args2, **kwargs2)
  File "./happy365/views.py", line 118, in post
    user = authenticate(username=username, password=password)
  File "/usr/local/lib/python2.7/dist-packages/django/contrib/auth/__init__.py", line 49, in authenticate
    user = backend.authenticate(**credentials)
  File "/usr/local/lib/python2.7/dist-packages/django/contrib/auth/backends.py", line 16, in authenticate
    user = UserModel._default_manager.get_by_natural_key(username)
  File "/usr/local/lib/python2.7/dist-packages/django/contrib/auth/models.py", line 167, in get_by_natural_key
    return self.get(**{self.model.USERNAME_FIELD: username})
  File "/usr/local/lib/python2.7/dist-packages/django/db/models/manager.py", line 151, in get
    return self.get_queryset().get(*args, **kwargs)
  File "/usr/local/lib/python2.7/dist-packages/django/db/models/query.py", line 304, in get
    num = len(clone)
  File "/usr/local/lib/python2.7/dist-packages/django/db/models/query.py", line 77, in __len__
    self._fetch_all()
  File "/usr/local/lib/python2.7/dist-packages/django/db/models/query.py", line 857, in _fetch_all
    self._result_cache = list(self.iterator())
  File "/usr/local/lib/python2.7/dist-packages/django/db/models/query.py", line 220, in iterator
    for row in compiler.results_iter():
  File "/usr/local/lib/python2.7/dist-packages/django/db/models/sql/compiler.py", line 713, in results_iter
    for rows in self.execute_sql(MULTI):
  File "/usr/local/lib/python2.7/dist-packages/django/db/models/sql/compiler.py", line 786, in execute_sql
    cursor.execute(sql, params)
  File "/usr/local/lib/python2.7/dist-packages/django/db/backends/util.py", line 69, in execute
    return super(CursorDebugWrapper, self).execute(sql, params)
  File "/usr/local/lib/python2.7/dist-packages/django/db/backends/util.py", line 53, in execute
    return self.cursor.execute(sql, params)
  File "/usr/local/lib/python2.7/dist-packages/django/db/utils.py", line 99, in __exit__
    six.reraise(dj_exc_type, dj_exc_value, traceback)
  File "/usr/local/lib/python2.7/dist-packages/django/db/backends/util.py", line 53, in execute
    return self.cursor.execute(sql, params)
  File "/usr/local/lib/python2.7/dist-packages/django/db/backends/mysql/base.py", line 124, in execute
    return self.cursor.execute(query, args)
  File "build/bdist.linux-x86_64/egg/MySQLdb/cursors.py", line 205, in execute
    self.errorhandler(self, exc, value)
  File "build/bdist.linux-x86_64/egg/MySQLdb/connections.py", line 36, in defaulterrorhandler
    raise errorclass, errorvalue
OperationalError: (1267, "Illegal mix of collations (latin1_swedish_ci,IMPLICIT) and (utf8_general_ci,COERCIBLE) for operation '='")
2014-08-04 15:19:55,415 [ERROR] django.request: Internal Server Error: /signin/
Traceback (most recent call last):
  File "/usr/local/lib/python2.7/dist-packages/django/core/handlers/base.py", line 112, in get_response
    response = wrapped_callback(request, *callback_args, **callback_kwargs)
  File "/usr/local/lib/python2.7/dist-packages/django/views/generic/base.py", line 69, in view
    return self.dispatch(request, *args, **kwargs)
  File "/usr/local/lib/python2.7/dist-packages/django/views/decorators/csrf.py", line 57, in wrapped_view
    return view_func(*args, **kwargs)
  File "/usr/local/lib/python2.7/dist-packages/rest_framework/views.py", line 400, in dispatch
    response = self.handle_exception(exc)
  File "/usr/local/lib/python2.7/dist-packages/rest_framework/views.py", line 397, in dispatch
    response = handler(request, *args, **kwargs)
  File "/usr/local/lib/python2.7/dist-packages/django/utils/decorators.py", line 29, in _wrapper
    return bound_func(*args, **kwargs)
  File "/usr/local/lib/python2.7/dist-packages/django/utils/decorators.py", line 99, in _wrapped_view
    response = view_func(request, *args, **kwargs)
  File "/usr/local/lib/python2.7/dist-packages/django/utils/decorators.py", line 25, in bound_func
    return func(self, *args2, **kwargs2)
  File "./happy365/views.py", line 118, in post
    user = authenticate(username=username, password=password)
  File "/usr/local/lib/python2.7/dist-packages/django/contrib/auth/__init__.py", line 49, in authenticate
    user = backend.authenticate(**credentials)
  File "/usr/local/lib/python2.7/dist-packages/django/contrib/auth/backends.py", line 16, in authenticate
    user = UserModel._default_manager.get_by_natural_key(username)
  File "/usr/local/lib/python2.7/dist-packages/django/contrib/auth/models.py", line 167, in get_by_natural_key
    return self.get(**{self.model.USERNAME_FIELD: username})
  File "/usr/local/lib/python2.7/dist-packages/django/db/models/manager.py", line 151, in get
    return self.get_queryset().get(*args, **kwargs)
  File "/usr/local/lib/python2.7/dist-packages/django/db/models/query.py", line 304, in get
    num = len(clone)
  File "/usr/local/lib/python2.7/dist-packages/django/db/models/query.py", line 77, in __len__
    self._fetch_all()
  File "/usr/local/lib/python2.7/dist-packages/django/db/models/query.py", line 857, in _fetch_all
    self._result_cache = list(self.iterator())
  File "/usr/local/lib/python2.7/dist-packages/django/db/models/query.py", line 220, in iterator
    for row in compiler.results_iter():
  File "/usr/local/lib/python2.7/dist-packages/django/db/models/sql/compiler.py", line 713, in results_iter
    for rows in self.execute_sql(MULTI):
  File "/usr/local/lib/python2.7/dist-packages/django/db/models/sql/compiler.py", line 786, in execute_sql
    cursor.execute(sql, params)
  File "/usr/local/lib/python2.7/dist-packages/django/db/backends/util.py", line 69, in execute
    return super(CursorDebugWrapper, self).execute(sql, params)
  File "/usr/local/lib/python2.7/dist-packages/django/db/backends/util.py", line 53, in execute
    return self.cursor.execute(sql, params)
  File "/usr/local/lib/python2.7/dist-packages/django/db/utils.py", line 99, in __exit__
    six.reraise(dj_exc_type, dj_exc_value, traceback)
  File "/usr/local/lib/python2.7/dist-packages/django/db/backends/util.py", line 53, in execute
    return self.cursor.execute(sql, params)
  File "/usr/local/lib/python2.7/dist-packages/django/db/backends/mysql/base.py", line 124, in execute
    return self.cursor.execute(query, args)
  File "build/bdist.linux-x86_64/egg/MySQLdb/cursors.py", line 205, in execute
    self.errorhandler(self, exc, value)
  File "build/bdist.linux-x86_64/egg/MySQLdb/connections.py", line 36, in defaulterrorhandler
    raise errorclass, errorvalue
OperationalError: (1267, "Illegal mix of collations (latin1_swedish_ci,IMPLICIT) and (utf8_general_ci,COERCIBLE) for operation '='")
2014-08-04 15:19:56,543 [ERROR] django.request: Internal Server Error: /signin/
Traceback (most recent call last):
  File "/usr/local/lib/python2.7/dist-packages/django/core/handlers/base.py", line 112, in get_response
    response = wrapped_callback(request, *callback_args, **callback_kwargs)
  File "/usr/local/lib/python2.7/dist-packages/django/views/generic/base.py", line 69, in view
    return self.dispatch(request, *args, **kwargs)
  File "/usr/local/lib/python2.7/dist-packages/django/views/decorators/csrf.py", line 57, in wrapped_view
    return view_func(*args, **kwargs)
  File "/usr/local/lib/python2.7/dist-packages/rest_framework/views.py", line 400, in dispatch
    response = self.handle_exception(exc)
  File "/usr/local/lib/python2.7/dist-packages/rest_framework/views.py", line 397, in dispatch
    response = handler(request, *args, **kwargs)
  File "/usr/local/lib/python2.7/dist-packages/django/utils/decorators.py", line 29, in _wrapper
    return bound_func(*args, **kwargs)
  File "/usr/local/lib/python2.7/dist-packages/django/utils/decorators.py", line 99, in _wrapped_view
    response = view_func(request, *args, **kwargs)
  File "/usr/local/lib/python2.7/dist-packages/django/utils/decorators.py", line 25, in bound_func
    return func(self, *args2, **kwargs2)
  File "./happy365/views.py", line 118, in post
    user = authenticate(username=username, password=password)
  File "/usr/local/lib/python2.7/dist-packages/django/contrib/auth/__init__.py", line 49, in authenticate
    user = backend.authenticate(**credentials)
  File "/usr/local/lib/python2.7/dist-packages/django/contrib/auth/backends.py", line 16, in authenticate
    user = UserModel._default_manager.get_by_natural_key(username)
  File "/usr/local/lib/python2.7/dist-packages/django/contrib/auth/models.py", line 167, in get_by_natural_key
    return self.get(**{self.model.USERNAME_FIELD: username})
  File "/usr/local/lib/python2.7/dist-packages/django/db/models/manager.py", line 151, in get
    return self.get_queryset().get(*args, **kwargs)
  File "/usr/local/lib/python2.7/dist-packages/django/db/models/query.py", line 304, in get
    num = len(clone)
  File "/usr/local/lib/python2.7/dist-packages/django/db/models/query.py", line 77, in __len__
    self._fetch_all()
  File "/usr/local/lib/python2.7/dist-packages/django/db/models/query.py", line 857, in _fetch_all
    self._result_cache = list(self.iterator())
  File "/usr/local/lib/python2.7/dist-packages/django/db/models/query.py", line 220, in iterator
    for row in compiler.results_iter():
  File "/usr/local/lib/python2.7/dist-packages/django/db/models/sql/compiler.py", line 713, in results_iter
    for rows in self.execute_sql(MULTI):
  File "/usr/local/lib/python2.7/dist-packages/django/db/models/sql/compiler.py", line 786, in execute_sql
    cursor.execute(sql, params)
  File "/usr/local/lib/python2.7/dist-packages/django/db/backends/util.py", line 69, in execute
    return super(CursorDebugWrapper, self).execute(sql, params)
  File "/usr/local/lib/python2.7/dist-packages/django/db/backends/util.py", line 53, in execute
    return self.cursor.execute(sql, params)
  File "/usr/local/lib/python2.7/dist-packages/django/db/utils.py", line 99, in __exit__
    six.reraise(dj_exc_type, dj_exc_value, traceback)
  File "/usr/local/lib/python2.7/dist-packages/django/db/backends/util.py", line 53, in execute
    return self.cursor.execute(sql, params)
  File "/usr/local/lib/python2.7/dist-packages/django/db/backends/mysql/base.py", line 124, in execute
    return self.cursor.execute(query, args)
  File "build/bdist.linux-x86_64/egg/MySQLdb/cursors.py", line 205, in execute
    self.errorhandler(self, exc, value)
  File "build/bdist.linux-x86_64/egg/MySQLdb/connections.py", line 36, in defaulterrorhandler
    raise errorclass, errorvalue
OperationalError: (1267, "Illegal mix of collations (latin1_swedish_ci,IMPLICIT) and (utf8_general_ci,COERCIBLE) for operation '='")
2014-08-04 15:19:57,699 [ERROR] django.request: Internal Server Error: /signin/
Traceback (most recent call last):
  File "/usr/local/lib/python2.7/dist-packages/django/core/handlers/base.py", line 112, in get_response
    response = wrapped_callback(request, *callback_args, **callback_kwargs)
  File "/usr/local/lib/python2.7/dist-packages/django/views/generic/base.py", line 69, in view
    return self.dispatch(request, *args, **kwargs)
  File "/usr/local/lib/python2.7/dist-packages/django/views/decorators/csrf.py", line 57, in wrapped_view
    return view_func(*args, **kwargs)
  File "/usr/local/lib/python2.7/dist-packages/rest_framework/views.py", line 400, in dispatch
    response = self.handle_exception(exc)
  File "/usr/local/lib/python2.7/dist-packages/rest_framework/views.py", line 397, in dispatch
    response = handler(request, *args, **kwargs)
  File "/usr/local/lib/python2.7/dist-packages/django/utils/decorators.py", line 29, in _wrapper
    return bound_func(*args, **kwargs)
  File "/usr/local/lib/python2.7/dist-packages/django/utils/decorators.py", line 99, in _wrapped_view
    response = view_func(request, *args, **kwargs)
  File "/usr/local/lib/python2.7/dist-packages/django/utils/decorators.py", line 25, in bound_func
    return func(self, *args2, **kwargs2)
  File "./happy365/views.py", line 118, in post
    user = authenticate(username=username, password=password)
  File "/usr/local/lib/python2.7/dist-packages/django/contrib/auth/__init__.py", line 49, in authenticate
    user = backend.authenticate(**credentials)
  File "/usr/local/lib/python2.7/dist-packages/django/contrib/auth/backends.py", line 16, in authenticate
    user = UserModel._default_manager.get_by_natural_key(username)
  File "/usr/local/lib/python2.7/dist-packages/django/contrib/auth/models.py", line 167, in get_by_natural_key
    return self.get(**{self.model.USERNAME_FIELD: username})
  File "/usr/local/lib/python2.7/dist-packages/django/db/models/manager.py", line 151, in get
    return self.get_queryset().get(*args, **kwargs)
  File "/usr/local/lib/python2.7/dist-packages/django/db/models/query.py", line 304, in get
    num = len(clone)
  File "/usr/local/lib/python2.7/dist-packages/django/db/models/query.py", line 77, in __len__
    self._fetch_all()
  File "/usr/local/lib/python2.7/dist-packages/django/db/models/query.py", line 857, in _fetch_all
    self._result_cache = list(self.iterator())
  File "/usr/local/lib/python2.7/dist-packages/django/db/models/query.py", line 220, in iterator
    for row in compiler.results_iter():
  File "/usr/local/lib/python2.7/dist-packages/django/db/models/sql/compiler.py", line 713, in results_iter
    for rows in self.execute_sql(MULTI):
  File "/usr/local/lib/python2.7/dist-packages/django/db/models/sql/compiler.py", line 786, in execute_sql
    cursor.execute(sql, params)
  File "/usr/local/lib/python2.7/dist-packages/django/db/backends/util.py", line 69, in execute
    return super(CursorDebugWrapper, self).execute(sql, params)
  File "/usr/local/lib/python2.7/dist-packages/django/db/backends/util.py", line 53, in execute
    return self.cursor.execute(sql, params)
  File "/usr/local/lib/python2.7/dist-packages/django/db/utils.py", line 99, in __exit__
    six.reraise(dj_exc_type, dj_exc_value, traceback)
  File "/usr/local/lib/python2.7/dist-packages/django/db/backends/util.py", line 53, in execute
    return self.cursor.execute(sql, params)
  File "/usr/local/lib/python2.7/dist-packages/django/db/backends/mysql/base.py", line 124, in execute
    return self.cursor.execute(query, args)
  File "build/bdist.linux-x86_64/egg/MySQLdb/cursors.py", line 205, in execute
    self.errorhandler(self, exc, value)
  File "build/bdist.linux-x86_64/egg/MySQLdb/connections.py", line 36, in defaulterrorhandler
    raise errorclass, errorvalue
OperationalError: (1267, "Illegal mix of collations (latin1_swedish_ci,IMPLICIT) and (utf8_general_ci,COERCIBLE) for operation '='")
2014-08-04 15:22:20,182 [WARNING] django.request: Not Found: /
2014-08-04 15:22:40,135 [ERROR] django.request: Internal Server Error: /token/
Traceback (most recent call last):
  File "/usr/local/lib/python2.7/dist-packages/django/core/handlers/base.py", line 112, in get_response
    response = wrapped_callback(request, *callback_args, **callback_kwargs)
  File "/usr/local/lib/python2.7/dist-packages/django/views/generic/base.py", line 69, in view
    return self.dispatch(request, *args, **kwargs)
  File "/usr/local/lib/python2.7/dist-packages/django/views/decorators/csrf.py", line 57, in wrapped_view
    return view_func(*args, **kwargs)
  File "/usr/local/lib/python2.7/dist-packages/rest_framework/views.py", line 400, in dispatch
    response = self.handle_exception(exc)
  File "/usr/local/lib/python2.7/dist-packages/rest_framework/views.py", line 397, in dispatch
    response = handler(request, *args, **kwargs)
  File "/usr/local/lib/python2.7/dist-packages/django/utils/decorators.py", line 29, in _wrapper
    return bound_func(*args, **kwargs)
  File "/usr/local/lib/python2.7/dist-packages/django/utils/decorators.py", line 99, in _wrapped_view
    response = view_func(request, *args, **kwargs)
  File "/usr/local/lib/python2.7/dist-packages/django/utils/decorators.py", line 25, in bound_func
    return func(self, *args2, **kwargs2)
  File "./happy365/views.py", line 207, in post
    token.save()
  File "/usr/local/lib/python2.7/dist-packages/django/db/models/base.py", line 545, in save
    force_update=force_update, update_fields=update_fields)
  File "/usr/local/lib/python2.7/dist-packages/django/db/models/base.py", line 573, in save_base
    updated = self._save_table(raw, cls, force_insert, force_update, using, update_fields)
  File "/usr/local/lib/python2.7/dist-packages/django/db/models/base.py", line 654, in _save_table
    result = self._do_insert(cls._base_manager, using, fields, update_pk, raw)
  File "/usr/local/lib/python2.7/dist-packages/django/db/models/base.py", line 687, in _do_insert
    using=using, raw=raw)
  File "/usr/local/lib/python2.7/dist-packages/django/db/models/manager.py", line 232, in _insert
    return insert_query(self.model, objs, fields, **kwargs)
  File "/usr/local/lib/python2.7/dist-packages/django/db/models/query.py", line 1514, in insert_query
    return query.get_compiler(using=using).execute_sql(return_id)
  File "/usr/local/lib/python2.7/dist-packages/django/db/models/sql/compiler.py", line 902, in execute_sql
    for sql, params in self.as_sql():
  File "/usr/local/lib/python2.7/dist-packages/django/db/models/sql/compiler.py", line 860, in as_sql
    for obj in self.query.objs
  File "/usr/local/lib/python2.7/dist-packages/django/db/models/fields/__init__.py", line 350, in get_db_prep_save
    prepared=False)
  File "/usr/local/lib/python2.7/dist-packages/django/db/models/fields/__init__.py", line 342, in get_db_prep_value
    value = self.get_prep_value(value)
  File "/usr/local/lib/python2.7/dist-packages/django/db/models/fields/__init__.py", line 1079, in get_prep_value
    return int(value)
ValueError: invalid literal for int() with base 10: '{"access_token":"2.00_gGqzB0XcX3ga2cb7addeemMTeAD","remind_in":"128240","expires_in":128240,"uid":"1829908071"}'
2014-08-04 15:26:36,441 [WARNING] django.request: Not Found: /
2014-08-04 15:29:54,307 [ERROR] django.request: Internal Server Error: /token/
Traceback (most recent call last):
  File "/usr/local/lib/python2.7/dist-packages/django/core/handlers/base.py", line 112, in get_response
    response = wrapped_callback(request, *callback_args, **callback_kwargs)
  File "/usr/local/lib/python2.7/dist-packages/django/views/generic/base.py", line 69, in view
    return self.dispatch(request, *args, **kwargs)
  File "/usr/local/lib/python2.7/dist-packages/django/views/decorators/csrf.py", line 57, in wrapped_view
    return view_func(*args, **kwargs)
  File "/usr/local/lib/python2.7/dist-packages/rest_framework/views.py", line 400, in dispatch
    response = self.handle_exception(exc)
  File "/usr/local/lib/python2.7/dist-packages/rest_framework/views.py", line 397, in dispatch
    response = handler(request, *args, **kwargs)
  File "/usr/local/lib/python2.7/dist-packages/django/utils/decorators.py", line 29, in _wrapper
    return bound_func(*args, **kwargs)
  File "/usr/local/lib/python2.7/dist-packages/django/utils/decorators.py", line 99, in _wrapped_view
    response = view_func(request, *args, **kwargs)
  File "/usr/local/lib/python2.7/dist-packages/django/utils/decorators.py", line 25, in bound_func
    return func(self, *args2, **kwargs2)
  File "./happy365/views.py", line 207, in post
    token.save()
  File "/usr/local/lib/python2.7/dist-packages/django/db/models/base.py", line 545, in save
    force_update=force_update, update_fields=update_fields)
  File "/usr/local/lib/python2.7/dist-packages/django/db/models/base.py", line 573, in save_base
    updated = self._save_table(raw, cls, force_insert, force_update, using, update_fields)
  File "/usr/local/lib/python2.7/dist-packages/django/db/models/base.py", line 654, in _save_table
    result = self._do_insert(cls._base_manager, using, fields, update_pk, raw)
  File "/usr/local/lib/python2.7/dist-packages/django/db/models/base.py", line 687, in _do_insert
    using=using, raw=raw)
  File "/usr/local/lib/python2.7/dist-packages/django/db/models/manager.py", line 232, in _insert
    return insert_query(self.model, objs, fields, **kwargs)
  File "/usr/local/lib/python2.7/dist-packages/django/db/models/query.py", line 1514, in insert_query
    return query.get_compiler(using=using).execute_sql(return_id)
  File "/usr/local/lib/python2.7/dist-packages/django/db/models/sql/compiler.py", line 902, in execute_sql
    for sql, params in self.as_sql():
  File "/usr/local/lib/python2.7/dist-packages/django/db/models/sql/compiler.py", line 860, in as_sql
    for obj in self.query.objs
  File "/usr/local/lib/python2.7/dist-packages/django/db/models/fields/__init__.py", line 350, in get_db_prep_save
    prepared=False)
  File "/usr/local/lib/python2.7/dist-packages/django/db/models/fields/__init__.py", line 342, in get_db_prep_value
    value = self.get_prep_value(value)
  File "/usr/local/lib/python2.7/dist-packages/django/db/models/fields/__init__.py", line 1079, in get_prep_value
    return int(value)
ValueError: invalid literal for int() with base 10: '{"access_token":"2.00_gGqzB0XcX3g50ee35bcbdYOoNOC","remind_in":"127805","expires_in":127805,"uid":"1829908071"}'
2014-08-04 15:47:09,567 [ERROR] django.request: Internal Server Error: /feed/
Traceback (most recent call last):
  File "/usr/local/lib/python2.7/dist-packages/django/core/handlers/base.py", line 112, in get_response
    response = wrapped_callback(request, *callback_args, **callback_kwargs)
  File "/usr/local/lib/python2.7/dist-packages/django/views/generic/base.py", line 69, in view
    return self.dispatch(request, *args, **kwargs)
  File "/usr/local/lib/python2.7/dist-packages/django/views/decorators/csrf.py", line 57, in wrapped_view
    return view_func(*args, **kwargs)
  File "/usr/local/lib/python2.7/dist-packages/rest_framework/views.py", line 400, in dispatch
    response = self.handle_exception(exc)
  File "/usr/local/lib/python2.7/dist-packages/rest_framework/views.py", line 397, in dispatch
    response = handler(request, *args, **kwargs)
  File "./happy365/views.py", line 278, in get
    scores=NLP.sentiment(txt)
UnboundLocalError: local variable 'txt' referenced before assignment
2014-08-04 15:47:11,236 [ERROR] django.request: Internal Server Error: /feed/
Traceback (most recent call last):
  File "/usr/local/lib/python2.7/dist-packages/django/core/handlers/base.py", line 112, in get_response
    response = wrapped_callback(request, *callback_args, **callback_kwargs)
  File "/usr/local/lib/python2.7/dist-packages/django/views/generic/base.py", line 69, in view
    return self.dispatch(request, *args, **kwargs)
  File "/usr/local/lib/python2.7/dist-packages/django/views/decorators/csrf.py", line 57, in wrapped_view
    return view_func(*args, **kwargs)
  File "/usr/local/lib/python2.7/dist-packages/rest_framework/views.py", line 400, in dispatch
    response = self.handle_exception(exc)
  File "/usr/local/lib/python2.7/dist-packages/rest_framework/views.py", line 397, in dispatch
    response = handler(request, *args, **kwargs)
  File "./happy365/views.py", line 278, in get
    scores=NLP.sentiment(txt)
UnboundLocalError: local variable 'txt' referenced before assignment
2014-08-04 15:47:13,516 [ERROR] django.request: Internal Server Error: /feed/
Traceback (most recent call last):
  File "/usr/local/lib/python2.7/dist-packages/django/core/handlers/base.py", line 112, in get_response
    response = wrapped_callback(request, *callback_args, **callback_kwargs)
  File "/usr/local/lib/python2.7/dist-packages/django/views/generic/base.py", line 69, in view
    return self.dispatch(request, *args, **kwargs)
  File "/usr/local/lib/python2.7/dist-packages/django/views/decorators/csrf.py", line 57, in wrapped_view
    return view_func(*args, **kwargs)
  File "/usr/local/lib/python2.7/dist-packages/rest_framework/views.py", line 400, in dispatch
    response = self.handle_exception(exc)
  File "/usr/local/lib/python2.7/dist-packages/rest_framework/views.py", line 397, in dispatch
    response = handler(request, *args, **kwargs)
  File "./happy365/views.py", line 278, in get
    scores=NLP.sentiment(txt)
UnboundLocalError: local variable 'txt' referenced before assignment
2014-08-04 15:47:18,743 [ERROR] django.request: Internal Server Error: /feed/
Traceback (most recent call last):
  File "/usr/local/lib/python2.7/dist-packages/django/core/handlers/base.py", line 112, in get_response
    response = wrapped_callback(request, *callback_args, **callback_kwargs)
  File "/usr/local/lib/python2.7/dist-packages/django/views/generic/base.py", line 69, in view
    return self.dispatch(request, *args, **kwargs)
  File "/usr/local/lib/python2.7/dist-packages/django/views/decorators/csrf.py", line 57, in wrapped_view
    return view_func(*args, **kwargs)
  File "/usr/local/lib/python2.7/dist-packages/rest_framework/views.py", line 400, in dispatch
    response = self.handle_exception(exc)
  File "/usr/local/lib/python2.7/dist-packages/rest_framework/views.py", line 397, in dispatch
    response = handler(request, *args, **kwargs)
  File "./happy365/views.py", line 278, in get
    scores=NLP.sentiment(txt)
UnboundLocalError: local variable 'txt' referenced before assignment
2014-08-04 15:47:20,104 [ERROR] django.request: Internal Server Error: /feed/
Traceback (most recent call last):
  File "/usr/local/lib/python2.7/dist-packages/django/core/handlers/base.py", line 112, in get_response
    response = wrapped_callback(request, *callback_args, **callback_kwargs)
  File "/usr/local/lib/python2.7/dist-packages/django/views/generic/base.py", line 69, in view
    return self.dispatch(request, *args, **kwargs)
  File "/usr/local/lib/python2.7/dist-packages/django/views/decorators/csrf.py", line 57, in wrapped_view
    return view_func(*args, **kwargs)
  File "/usr/local/lib/python2.7/dist-packages/rest_framework/views.py", line 400, in dispatch
    response = self.handle_exception(exc)
  File "/usr/local/lib/python2.7/dist-packages/rest_framework/views.py", line 397, in dispatch
    response = handler(request, *args, **kwargs)
  File "./happy365/views.py", line 278, in get
    scores=NLP.sentiment(txt)
UnboundLocalError: local variable 'txt' referenced before assignment
2014-08-04 15:47:52,640 [ERROR] django.request: Internal Server Error: /feed/
Traceback (most recent call last):
  File "/usr/local/lib/python2.7/dist-packages/django/core/handlers/base.py", line 112, in get_response
    response = wrapped_callback(request, *callback_args, **callback_kwargs)
  File "/usr/local/lib/python2.7/dist-packages/django/views/generic/base.py", line 69, in view
    return self.dispatch(request, *args, **kwargs)
  File "/usr/local/lib/python2.7/dist-packages/django/views/decorators/csrf.py", line 57, in wrapped_view
    return view_func(*args, **kwargs)
  File "/usr/local/lib/python2.7/dist-packages/rest_framework/views.py", line 400, in dispatch
    response = self.handle_exception(exc)
  File "/usr/local/lib/python2.7/dist-packages/rest_framework/views.py", line 397, in dispatch
    response = handler(request, *args, **kwargs)
  File "./happy365/views.py", line 278, in get
    scores=NLP.sentiment(txt)
UnboundLocalError: local variable 'txt' referenced before assignment
2014-08-04 15:48:08,709 [ERROR] django.request: Internal Server Error: /feed/
Traceback (most recent call last):
  File "/usr/local/lib/python2.7/dist-packages/django/core/handlers/base.py", line 112, in get_response
    response = wrapped_callback(request, *callback_args, **callback_kwargs)
  File "/usr/local/lib/python2.7/dist-packages/django/views/generic/base.py", line 69, in view
    return self.dispatch(request, *args, **kwargs)
  File "/usr/local/lib/python2.7/dist-packages/django/views/decorators/csrf.py", line 57, in wrapped_view
    return view_func(*args, **kwargs)
  File "/usr/local/lib/python2.7/dist-packages/rest_framework/views.py", line 400, in dispatch
    response = self.handle_exception(exc)
  File "/usr/local/lib/python2.7/dist-packages/rest_framework/views.py", line 397, in dispatch
    response = handler(request, *args, **kwargs)
  File "./happy365/views.py", line 278, in get
    scores=NLP.sentiment(txt)
UnboundLocalError: local variable 'txt' referenced before assignment
2014-08-04 15:48:12,740 [ERROR] django.request: Internal Server Error: /feed/
Traceback (most recent call last):
  File "/usr/local/lib/python2.7/dist-packages/django/core/handlers/base.py", line 112, in get_response
    response = wrapped_callback(request, *callback_args, **callback_kwargs)
  File "/usr/local/lib/python2.7/dist-packages/django/views/generic/base.py", line 69, in view
    return self.dispatch(request, *args, **kwargs)
  File "/usr/local/lib/python2.7/dist-packages/django/views/decorators/csrf.py", line 57, in wrapped_view
    return view_func(*args, **kwargs)
  File "/usr/local/lib/python2.7/dist-packages/rest_framework/views.py", line 400, in dispatch
    response = self.handle_exception(exc)
  File "/usr/local/lib/python2.7/dist-packages/rest_framework/views.py", line 397, in dispatch
    response = handler(request, *args, **kwargs)
  File "./happy365/views.py", line 278, in get
    scores=NLP.sentiment(txt)
UnboundLocalError: local variable 'txt' referenced before assignment
2014-08-04 15:52:17,012 [ERROR] django.request: Internal Server Error: /feed/
Traceback (most recent call last):
  File "/usr/local/lib/python2.7/dist-packages/django/core/handlers/base.py", line 112, in get_response
    response = wrapped_callback(request, *callback_args, **callback_kwargs)
  File "/usr/local/lib/python2.7/dist-packages/django/views/generic/base.py", line 69, in view
    return self.dispatch(request, *args, **kwargs)
  File "/usr/local/lib/python2.7/dist-packages/django/views/decorators/csrf.py", line 57, in wrapped_view
    return view_func(*args, **kwargs)
  File "/usr/local/lib/python2.7/dist-packages/rest_framework/views.py", line 400, in dispatch
    response = self.handle_exception(exc)
  File "/usr/local/lib/python2.7/dist-packages/rest_framework/views.py", line 397, in dispatch
    response = handler(request, *args, **kwargs)
  File "./happy365/views.py", line 278, in get
    scores=NLP.sentiment(txt)
UnboundLocalError: local variable 'txt' referenced before assignment
2014-08-04 15:52:20,986 [ERROR] django.request: Internal Server Error: /feed/
Traceback (most recent call last):
  File "/usr/local/lib/python2.7/dist-packages/django/core/handlers/base.py", line 112, in get_response
    response = wrapped_callback(request, *callback_args, **callback_kwargs)
  File "/usr/local/lib/python2.7/dist-packages/django/views/generic/base.py", line 69, in view
    return self.dispatch(request, *args, **kwargs)
  File "/usr/local/lib/python2.7/dist-packages/django/views/decorators/csrf.py", line 57, in wrapped_view
    return view_func(*args, **kwargs)
  File "/usr/local/lib/python2.7/dist-packages/rest_framework/views.py", line 400, in dispatch
    response = self.handle_exception(exc)
  File "/usr/local/lib/python2.7/dist-packages/rest_framework/views.py", line 397, in dispatch
    response = handler(request, *args, **kwargs)
  File "./happy365/views.py", line 278, in get
    scores=NLP.sentiment(txt)
UnboundLocalError: local variable 'txt' referenced before assignment
2014-08-04 15:52:54,716 [ERROR] django.request: Internal Server Error: /feed/
Traceback (most recent call last):
  File "/usr/local/lib/python2.7/dist-packages/django/core/handlers/base.py", line 112, in get_response
    response = wrapped_callback(request, *callback_args, **callback_kwargs)
  File "/usr/local/lib/python2.7/dist-packages/django/views/generic/base.py", line 69, in view
    return self.dispatch(request, *args, **kwargs)
  File "/usr/local/lib/python2.7/dist-packages/django/views/decorators/csrf.py", line 57, in wrapped_view
    return view_func(*args, **kwargs)
  File "/usr/local/lib/python2.7/dist-packages/rest_framework/views.py", line 400, in dispatch
    response = self.handle_exception(exc)
  File "/usr/local/lib/python2.7/dist-packages/rest_framework/views.py", line 397, in dispatch
    response = handler(request, *args, **kwargs)
  File "./happy365/views.py", line 278, in get
    scores=NLP.sentiment(txt)
UnboundLocalError: local variable 'txt' referenced before assignment
2014-08-04 15:53:00,383 [ERROR] django.request: Internal Server Error: /feed/
Traceback (most recent call last):
  File "/usr/local/lib/python2.7/dist-packages/django/core/handlers/base.py", line 112, in get_response
    response = wrapped_callback(request, *callback_args, **callback_kwargs)
  File "/usr/local/lib/python2.7/dist-packages/django/views/generic/base.py", line 69, in view
    return self.dispatch(request, *args, **kwargs)
  File "/usr/local/lib/python2.7/dist-packages/django/views/decorators/csrf.py", line 57, in wrapped_view
    return view_func(*args, **kwargs)
  File "/usr/local/lib/python2.7/dist-packages/rest_framework/views.py", line 400, in dispatch
    response = self.handle_exception(exc)
  File "/usr/local/lib/python2.7/dist-packages/rest_framework/views.py", line 397, in dispatch
    response = handler(request, *args, **kwargs)
  File "./happy365/views.py", line 278, in get
    scores=NLP.sentiment(txt)
UnboundLocalError: local variable 'txt' referenced before assignment
2014-08-04 15:53:08,426 [ERROR] django.request: Internal Server Error: /feed/
Traceback (most recent call last):
  File "/usr/local/lib/python2.7/dist-packages/django/core/handlers/base.py", line 112, in get_response
    response = wrapped_callback(request, *callback_args, **callback_kwargs)
  File "/usr/local/lib/python2.7/dist-packages/django/views/generic/base.py", line 69, in view
    return self.dispatch(request, *args, **kwargs)
  File "/usr/local/lib/python2.7/dist-packages/django/views/decorators/csrf.py", line 57, in wrapped_view
    return view_func(*args, **kwargs)
  File "/usr/local/lib/python2.7/dist-packages/rest_framework/views.py", line 400, in dispatch
    response = self.handle_exception(exc)
  File "/usr/local/lib/python2.7/dist-packages/rest_framework/views.py", line 397, in dispatch
    response = handler(request, *args, **kwargs)
  File "./happy365/views.py", line 278, in get
    scores=NLP.sentiment(txt)
UnboundLocalError: local variable 'txt' referenced before assignment
2014-08-04 15:53:13,863 [ERROR] django.request: Internal Server Error: /feed/
Traceback (most recent call last):
  File "/usr/local/lib/python2.7/dist-packages/django/core/handlers/base.py", line 112, in get_response
    response = wrapped_callback(request, *callback_args, **callback_kwargs)
  File "/usr/local/lib/python2.7/dist-packages/django/views/generic/base.py", line 69, in view
    return self.dispatch(request, *args, **kwargs)
  File "/usr/local/lib/python2.7/dist-packages/django/views/decorators/csrf.py", line 57, in wrapped_view
    return view_func(*args, **kwargs)
  File "/usr/local/lib/python2.7/dist-packages/rest_framework/views.py", line 400, in dispatch
    response = self.handle_exception(exc)
  File "/usr/local/lib/python2.7/dist-packages/rest_framework/views.py", line 397, in dispatch
    response = handler(request, *args, **kwargs)
  File "./happy365/views.py", line 278, in get
    scores=NLP.sentiment(txt)
UnboundLocalError: local variable 'txt' referenced before assignment
2014-08-04 15:54:02,853 [ERROR] django.request: Internal Server Error: /token/
Traceback (most recent call last):
  File "/usr/local/lib/python2.7/dist-packages/django/core/handlers/base.py", line 112, in get_response
    response = wrapped_callback(request, *callback_args, **callback_kwargs)
  File "/usr/local/lib/python2.7/dist-packages/django/views/generic/base.py", line 69, in view
    return self.dispatch(request, *args, **kwargs)
  File "/usr/local/lib/python2.7/dist-packages/django/views/decorators/csrf.py", line 57, in wrapped_view
    return view_func(*args, **kwargs)
  File "/usr/local/lib/python2.7/dist-packages/rest_framework/views.py", line 400, in dispatch
    response = self.handle_exception(exc)
  File "/usr/local/lib/python2.7/dist-packages/rest_framework/views.py", line 397, in dispatch
    response = handler(request, *args, **kwargs)
  File "/usr/local/lib/python2.7/dist-packages/django/utils/decorators.py", line 29, in _wrapper
    return bound_func(*args, **kwargs)
  File "/usr/local/lib/python2.7/dist-packages/django/utils/decorators.py", line 99, in _wrapped_view
    response = view_func(request, *args, **kwargs)
  File "/usr/local/lib/python2.7/dist-packages/django/utils/decorators.py", line 25, in bound_func
    return func(self, *args2, **kwargs2)
  File "./happy365/views.py", line 207, in post
    token.save()
  File "/usr/local/lib/python2.7/dist-packages/django/db/models/base.py", line 545, in save
    force_update=force_update, update_fields=update_fields)
  File "/usr/local/lib/python2.7/dist-packages/django/db/models/base.py", line 573, in save_base
    updated = self._save_table(raw, cls, force_insert, force_update, using, update_fields)
  File "/usr/local/lib/python2.7/dist-packages/django/db/models/base.py", line 654, in _save_table
    result = self._do_insert(cls._base_manager, using, fields, update_pk, raw)
  File "/usr/local/lib/python2.7/dist-packages/django/db/models/base.py", line 687, in _do_insert
    using=using, raw=raw)
  File "/usr/local/lib/python2.7/dist-packages/django/db/models/manager.py", line 232, in _insert
    return insert_query(self.model, objs, fields, **kwargs)
  File "/usr/local/lib/python2.7/dist-packages/django/db/models/query.py", line 1514, in insert_query
    return query.get_compiler(using=using).execute_sql(return_id)
  File "/usr/local/lib/python2.7/dist-packages/django/db/models/sql/compiler.py", line 903, in execute_sql
    cursor.execute(sql, params)
  File "/usr/local/lib/python2.7/dist-packages/django/db/backends/util.py", line 69, in execute
    return super(CursorDebugWrapper, self).execute(sql, params)
  File "/usr/local/lib/python2.7/dist-packages/django/db/backends/util.py", line 53, in execute
    return self.cursor.execute(sql, params)
  File "/usr/local/lib/python2.7/dist-packages/django/db/utils.py", line 99, in __exit__
    six.reraise(dj_exc_type, dj_exc_value, traceback)
  File "/usr/local/lib/python2.7/dist-packages/django/db/backends/util.py", line 53, in execute
    return self.cursor.execute(sql, params)
  File "/usr/local/lib/python2.7/dist-packages/django/db/backends/mysql/base.py", line 124, in execute
    return self.cursor.execute(query, args)
  File "build/bdist.linux-x86_64/egg/MySQLdb/cursors.py", line 205, in execute
    self.errorhandler(self, exc, value)
  File "build/bdist.linux-x86_64/egg/MySQLdb/connections.py", line 36, in defaulterrorhandler
    raise errorclass, errorvalue
IntegrityError: (1062, "Duplicate entry '1829908071' for key 'weibo_uid'")
2014-08-04 15:54:57,000 [ERROR] django.request: Internal Server Error: /token/
Traceback (most recent call last):
  File "/usr/local/lib/python2.7/dist-packages/django/core/handlers/base.py", line 112, in get_response
    response = wrapped_callback(request, *callback_args, **callback_kwargs)
  File "/usr/local/lib/python2.7/dist-packages/django/views/generic/base.py", line 69, in view
    return self.dispatch(request, *args, **kwargs)
  File "/usr/local/lib/python2.7/dist-packages/django/views/decorators/csrf.py", line 57, in wrapped_view
    return view_func(*args, **kwargs)
  File "/usr/local/lib/python2.7/dist-packages/rest_framework/views.py", line 400, in dispatch
    response = self.handle_exception(exc)
  File "/usr/local/lib/python2.7/dist-packages/rest_framework/views.py", line 397, in dispatch
    response = handler(request, *args, **kwargs)
  File "/usr/local/lib/python2.7/dist-packages/django/utils/decorators.py", line 29, in _wrapper
    return bound_func(*args, **kwargs)
  File "/usr/local/lib/python2.7/dist-packages/django/utils/decorators.py", line 99, in _wrapped_view
    response = view_func(request, *args, **kwargs)
  File "/usr/local/lib/python2.7/dist-packages/django/utils/decorators.py", line 25, in bound_func
    return func(self, *args2, **kwargs2)
  File "./happy365/views.py", line 207, in post
    token.save()
  File "/usr/local/lib/python2.7/dist-packages/django/db/models/base.py", line 545, in save
    force_update=force_update, update_fields=update_fields)
  File "/usr/local/lib/python2.7/dist-packages/django/db/models/base.py", line 573, in save_base
    updated = self._save_table(raw, cls, force_insert, force_update, using, update_fields)
  File "/usr/local/lib/python2.7/dist-packages/django/db/models/base.py", line 654, in _save_table
    result = self._do_insert(cls._base_manager, using, fields, update_pk, raw)
  File "/usr/local/lib/python2.7/dist-packages/django/db/models/base.py", line 687, in _do_insert
    using=using, raw=raw)
  File "/usr/local/lib/python2.7/dist-packages/django/db/models/manager.py", line 232, in _insert
    return insert_query(self.model, objs, fields, **kwargs)
  File "/usr/local/lib/python2.7/dist-packages/django/db/models/query.py", line 1514, in insert_query
    return query.get_compiler(using=using).execute_sql(return_id)
  File "/usr/local/lib/python2.7/dist-packages/django/db/models/sql/compiler.py", line 903, in execute_sql
    cursor.execute(sql, params)
  File "/usr/local/lib/python2.7/dist-packages/django/db/backends/util.py", line 69, in execute
    return super(CursorDebugWrapper, self).execute(sql, params)
  File "/usr/local/lib/python2.7/dist-packages/django/db/backends/util.py", line 53, in execute
    return self.cursor.execute(sql, params)
  File "/usr/local/lib/python2.7/dist-packages/django/db/utils.py", line 99, in __exit__
    six.reraise(dj_exc_type, dj_exc_value, traceback)
  File "/usr/local/lib/python2.7/dist-packages/django/db/backends/util.py", line 53, in execute
    return self.cursor.execute(sql, params)
  File "/usr/local/lib/python2.7/dist-packages/django/db/backends/mysql/base.py", line 124, in execute
    return self.cursor.execute(query, args)
  File "build/bdist.linux-x86_64/egg/MySQLdb/cursors.py", line 205, in execute
    self.errorhandler(self, exc, value)
  File "build/bdist.linux-x86_64/egg/MySQLdb/connections.py", line 36, in defaulterrorhandler
    raise errorclass, errorvalue
IntegrityError: (1062, "Duplicate entry '1829908071' for key 'weibo_uid'")
2014-08-04 15:55:57,797 [ERROR] django.request: Internal Server Error: /token/
Traceback (most recent call last):
  File "/usr/local/lib/python2.7/dist-packages/django/core/handlers/base.py", line 112, in get_response
    response = wrapped_callback(request, *callback_args, **callback_kwargs)
  File "/usr/local/lib/python2.7/dist-packages/django/views/generic/base.py", line 69, in view
    return self.dispatch(request, *args, **kwargs)
  File "/usr/local/lib/python2.7/dist-packages/django/views/decorators/csrf.py", line 57, in wrapped_view
    return view_func(*args, **kwargs)
  File "/usr/local/lib/python2.7/dist-packages/rest_framework/views.py", line 400, in dispatch
    response = self.handle_exception(exc)
  File "/usr/local/lib/python2.7/dist-packages/rest_framework/views.py", line 397, in dispatch
    response = handler(request, *args, **kwargs)
  File "/usr/local/lib/python2.7/dist-packages/django/utils/decorators.py", line 29, in _wrapper
    return bound_func(*args, **kwargs)
  File "/usr/local/lib/python2.7/dist-packages/django/utils/decorators.py", line 99, in _wrapped_view
    response = view_func(request, *args, **kwargs)
  File "/usr/local/lib/python2.7/dist-packages/django/utils/decorators.py", line 25, in bound_func
    return func(self, *args2, **kwargs2)
  File "./happy365/views.py", line 207, in post
    token.save()
  File "/usr/local/lib/python2.7/dist-packages/django/db/models/base.py", line 545, in save
    force_update=force_update, update_fields=update_fields)
  File "/usr/local/lib/python2.7/dist-packages/django/db/models/base.py", line 573, in save_base
    updated = self._save_table(raw, cls, force_insert, force_update, using, update_fields)
  File "/usr/local/lib/python2.7/dist-packages/django/db/models/base.py", line 654, in _save_table
    result = self._do_insert(cls._base_manager, using, fields, update_pk, raw)
  File "/usr/local/lib/python2.7/dist-packages/django/db/models/base.py", line 687, in _do_insert
    using=using, raw=raw)
  File "/usr/local/lib/python2.7/dist-packages/django/db/models/manager.py", line 232, in _insert
    return insert_query(self.model, objs, fields, **kwargs)
  File "/usr/local/lib/python2.7/dist-packages/django/db/models/query.py", line 1514, in insert_query
    return query.get_compiler(using=using).execute_sql(return_id)
  File "/usr/local/lib/python2.7/dist-packages/django/db/models/sql/compiler.py", line 903, in execute_sql
    cursor.execute(sql, params)
  File "/usr/local/lib/python2.7/dist-packages/django/db/backends/util.py", line 69, in execute
    return super(CursorDebugWrapper, self).execute(sql, params)
  File "/usr/local/lib/python2.7/dist-packages/django/db/backends/util.py", line 53, in execute
    return self.cursor.execute(sql, params)
  File "/usr/local/lib/python2.7/dist-packages/django/db/utils.py", line 99, in __exit__
    six.reraise(dj_exc_type, dj_exc_value, traceback)
  File "/usr/local/lib/python2.7/dist-packages/django/db/backends/util.py", line 53, in execute
    return self.cursor.execute(sql, params)
  File "/usr/local/lib/python2.7/dist-packages/django/db/backends/mysql/base.py", line 124, in execute
    return self.cursor.execute(query, args)
  File "build/bdist.linux-x86_64/egg/MySQLdb/cursors.py", line 205, in execute
    self.errorhandler(self, exc, value)
  File "build/bdist.linux-x86_64/egg/MySQLdb/connections.py", line 36, in defaulterrorhandler
    raise errorclass, errorvalue
IntegrityError: (1062, "Duplicate entry '1829908071' for key 'weibo_uid'")
2014-08-04 16:34:59,267 [ERROR] django.request: Internal Server Error: /feed/
Traceback (most recent call last):
  File "/usr/local/lib/python2.7/dist-packages/django/core/handlers/base.py", line 112, in get_response
    response = wrapped_callback(request, *callback_args, **callback_kwargs)
  File "/usr/local/lib/python2.7/dist-packages/django/views/generic/base.py", line 69, in view
    return self.dispatch(request, *args, **kwargs)
  File "/usr/local/lib/python2.7/dist-packages/django/views/decorators/csrf.py", line 57, in wrapped_view
    return view_func(*args, **kwargs)
  File "/usr/local/lib/python2.7/dist-packages/rest_framework/views.py", line 400, in dispatch
    response = self.handle_exception(exc)
  File "/usr/local/lib/python2.7/dist-packages/rest_framework/views.py", line 397, in dispatch
    response = handler(request, *args, **kwargs)
  File "./happy365/views.py", line 278, in get
    scores=NLP.sentiment(txt)
UnboundLocalError: local variable 'txt' referenced before assignment
2014-08-04 16:35:01,977 [ERROR] django.request: Internal Server Error: /feed/
Traceback (most recent call last):
  File "/usr/local/lib/python2.7/dist-packages/django/core/handlers/base.py", line 112, in get_response
    response = wrapped_callback(request, *callback_args, **callback_kwargs)
  File "/usr/local/lib/python2.7/dist-packages/django/views/generic/base.py", line 69, in view
    return self.dispatch(request, *args, **kwargs)
  File "/usr/local/lib/python2.7/dist-packages/django/views/decorators/csrf.py", line 57, in wrapped_view
    return view_func(*args, **kwargs)
  File "/usr/local/lib/python2.7/dist-packages/rest_framework/views.py", line 400, in dispatch
    response = self.handle_exception(exc)
  File "/usr/local/lib/python2.7/dist-packages/rest_framework/views.py", line 397, in dispatch
    response = handler(request, *args, **kwargs)
  File "./happy365/views.py", line 278, in get
    scores=NLP.sentiment(txt)
UnboundLocalError: local variable 'txt' referenced before assignment
2014-08-04 16:35:03,659 [ERROR] django.request: Internal Server Error: /feed/
Traceback (most recent call last):
  File "/usr/local/lib/python2.7/dist-packages/django/core/handlers/base.py", line 112, in get_response
    response = wrapped_callback(request, *callback_args, **callback_kwargs)
  File "/usr/local/lib/python2.7/dist-packages/django/views/generic/base.py", line 69, in view
    return self.dispatch(request, *args, **kwargs)
  File "/usr/local/lib/python2.7/dist-packages/django/views/decorators/csrf.py", line 57, in wrapped_view
    return view_func(*args, **kwargs)
  File "/usr/local/lib/python2.7/dist-packages/rest_framework/views.py", line 400, in dispatch
    response = self.handle_exception(exc)
  File "/usr/local/lib/python2.7/dist-packages/rest_framework/views.py", line 397, in dispatch
    response = handler(request, *args, **kwargs)
  File "./happy365/views.py", line 278, in get
    scores=NLP.sentiment(txt)
UnboundLocalError: local variable 'txt' referenced before assignment
2014-08-04 16:35:19,828 [ERROR] django.request: Internal Server Error: /feed/
Traceback (most recent call last):
  File "/usr/local/lib/python2.7/dist-packages/django/core/handlers/base.py", line 112, in get_response
    response = wrapped_callback(request, *callback_args, **callback_kwargs)
  File "/usr/local/lib/python2.7/dist-packages/django/views/generic/base.py", line 69, in view
    return self.dispatch(request, *args, **kwargs)
  File "/usr/local/lib/python2.7/dist-packages/django/views/decorators/csrf.py", line 57, in wrapped_view
    return view_func(*args, **kwargs)
  File "/usr/local/lib/python2.7/dist-packages/rest_framework/views.py", line 400, in dispatch
    response = self.handle_exception(exc)
  File "/usr/local/lib/python2.7/dist-packages/rest_framework/views.py", line 397, in dispatch
    response = handler(request, *args, **kwargs)
  File "./happy365/views.py", line 278, in get
    scores=NLP.sentiment(txt)
UnboundLocalError: local variable 'txt' referenced before assignment
2014-08-04 16:36:29,745 [WARNING] django.request: Not Found: /
2014-08-04 16:45:11,796 [WARNING] django.request: Not Found: /
2014-08-04 16:48:19,981 [ERROR] django.request: Internal Server Error: /feed/
Traceback (most recent call last):
  File "/usr/local/lib/python2.7/dist-packages/django/core/handlers/base.py", line 112, in get_response
    response = wrapped_callback(request, *callback_args, **callback_kwargs)
  File "/usr/local/lib/python2.7/dist-packages/django/views/generic/base.py", line 69, in view
    return self.dispatch(request, *args, **kwargs)
  File "/usr/local/lib/python2.7/dist-packages/django/views/decorators/csrf.py", line 57, in wrapped_view
    return view_func(*args, **kwargs)
  File "/usr/local/lib/python2.7/dist-packages/rest_framework/views.py", line 400, in dispatch
    response = self.handle_exception(exc)
  File "/usr/local/lib/python2.7/dist-packages/rest_framework/views.py", line 397, in dispatch
    response = handler(request, *args, **kwargs)
  File "./happy365/views.py", line 278, in get
    scores=NLP.sentiment(txt)
UnboundLocalError: local variable 'txt' referenced before assignment
2014-08-04 16:48:21,274 [ERROR] django.request: Internal Server Error: /feed/
Traceback (most recent call last):
  File "/usr/local/lib/python2.7/dist-packages/django/core/handlers/base.py", line 112, in get_response
    response = wrapped_callback(request, *callback_args, **callback_kwargs)
  File "/usr/local/lib/python2.7/dist-packages/django/views/generic/base.py", line 69, in view
    return self.dispatch(request, *args, **kwargs)
  File "/usr/local/lib/python2.7/dist-packages/django/views/decorators/csrf.py", line 57, in wrapped_view
    return view_func(*args, **kwargs)
  File "/usr/local/lib/python2.7/dist-packages/rest_framework/views.py", line 400, in dispatch
    response = self.handle_exception(exc)
  File "/usr/local/lib/python2.7/dist-packages/rest_framework/views.py", line 397, in dispatch
    response = handler(request, *args, **kwargs)
  File "./happy365/views.py", line 278, in get
    scores=NLP.sentiment(txt)
UnboundLocalError: local variable 'txt' referenced before assignment
2014-08-04 16:48:22,219 [ERROR] django.request: Internal Server Error: /feed/
Traceback (most recent call last):
  File "/usr/local/lib/python2.7/dist-packages/django/core/handlers/base.py", line 112, in get_response
    response = wrapped_callback(request, *callback_args, **callback_kwargs)
  File "/usr/local/lib/python2.7/dist-packages/django/views/generic/base.py", line 69, in view
    return self.dispatch(request, *args, **kwargs)
  File "/usr/local/lib/python2.7/dist-packages/django/views/decorators/csrf.py", line 57, in wrapped_view
    return view_func(*args, **kwargs)
  File "/usr/local/lib/python2.7/dist-packages/rest_framework/views.py", line 400, in dispatch
    response = self.handle_exception(exc)
  File "/usr/local/lib/python2.7/dist-packages/rest_framework/views.py", line 397, in dispatch
    response = handler(request, *args, **kwargs)
  File "./happy365/views.py", line 278, in get
    scores=NLP.sentiment(txt)
UnboundLocalError: local variable 'txt' referenced before assignment
2014-08-04 16:58:30,647 [WARNING] django.request: Not Found: /
2014-08-04 17:18:48,197 [WARNING] django.request: Not Found: /web-console/ServerInfo.jsp
2014-08-04 17:26:09,235 [WARNING] django.request: Not Found: /
2014-08-04 17:43:48,449 [WARNING] django.request: Not Found: /
2014-08-04 17:48:25,182 [WARNING] django.request: Not Found: /
2014-08-04 18:39:10,050 [WARNING] django.request: Not Found: /
2014-08-04 19:33:58,924 [WARNING] django.request: Not Found: /
2014-08-04 21:00:13,000 [WARNING] django.request: Not Found: /
2014-08-04 21:24:47,767 [WARNING] django.request: Not Found: /
2014-08-04 22:22:53,116 [WARNING] django.request: Not Found: /
2014-08-04 22:47:32,739 [WARNING] django.request: Not Found: /
2014-08-04 23:36:27,912 [WARNING] django.request: Not Found: /
2014-08-04 23:48:13,732 [ERROR] django.request: Internal Server Error: /feed/
Traceback (most recent call last):
  File "/usr/local/lib/python2.7/dist-packages/django/core/handlers/base.py", line 112, in get_response
    response = wrapped_callback(request, *callback_args, **callback_kwargs)
  File "/usr/local/lib/python2.7/dist-packages/django/views/generic/base.py", line 69, in view
    return self.dispatch(request, *args, **kwargs)
  File "/usr/local/lib/python2.7/dist-packages/django/views/decorators/csrf.py", line 57, in wrapped_view
    return view_func(*args, **kwargs)
  File "/usr/local/lib/python2.7/dist-packages/rest_framework/views.py", line 400, in dispatch
    response = self.handle_exception(exc)
  File "/usr/local/lib/python2.7/dist-packages/rest_framework/views.py", line 397, in dispatch
    response = handler(request, *args, **kwargs)
  File "./happy365/views.py", line 278, in get
    scores=NLP.sentiment(txt)
UnboundLocalError: local variable 'txt' referenced before assignment
2014-08-04 23:48:17,761 [ERROR] django.request: Internal Server Error: /feed/
Traceback (most recent call last):
  File "/usr/local/lib/python2.7/dist-packages/django/core/handlers/base.py", line 112, in get_response
    response = wrapped_callback(request, *callback_args, **callback_kwargs)
  File "/usr/local/lib/python2.7/dist-packages/django/views/generic/base.py", line 69, in view
    return self.dispatch(request, *args, **kwargs)
  File "/usr/local/lib/python2.7/dist-packages/django/views/decorators/csrf.py", line 57, in wrapped_view
    return view_func(*args, **kwargs)
  File "/usr/local/lib/python2.7/dist-packages/rest_framework/views.py", line 400, in dispatch
    response = self.handle_exception(exc)
  File "/usr/local/lib/python2.7/dist-packages/rest_framework/views.py", line 397, in dispatch
    response = handler(request, *args, **kwargs)
  File "./happy365/views.py", line 278, in get
    scores=NLP.sentiment(txt)
UnboundLocalError: local variable 'txt' referenced before assignment
2014-08-04 23:59:34,502 [ERROR] django.request: Internal Server Error: /feed/
Traceback (most recent call last):
  File "/usr/local/lib/python2.7/dist-packages/django/core/handlers/base.py", line 112, in get_response
    response = wrapped_callback(request, *callback_args, **callback_kwargs)
  File "/usr/local/lib/python2.7/dist-packages/django/views/generic/base.py", line 69, in view
    return self.dispatch(request, *args, **kwargs)
  File "/usr/local/lib/python2.7/dist-packages/django/views/decorators/csrf.py", line 57, in wrapped_view
    return view_func(*args, **kwargs)
  File "/usr/local/lib/python2.7/dist-packages/rest_framework/views.py", line 400, in dispatch
    response = self.handle_exception(exc)
  File "/usr/local/lib/python2.7/dist-packages/rest_framework/views.py", line 397, in dispatch
    response = handler(request, *args, **kwargs)
  File "./happy365/views.py", line 278, in get
    scores=NLP.sentiment(txt)
UnboundLocalError: local variable 'txt' referenced before assignment
2014-08-04 23:59:49,631 [ERROR] django.request: Internal Server Error: /feed/
Traceback (most recent call last):
  File "/usr/local/lib/python2.7/dist-packages/django/core/handlers/base.py", line 112, in get_response
    response = wrapped_callback(request, *callback_args, **callback_kwargs)
  File "/usr/local/lib/python2.7/dist-packages/django/views/generic/base.py", line 69, in view
    return self.dispatch(request, *args, **kwargs)
  File "/usr/local/lib/python2.7/dist-packages/django/views/decorators/csrf.py", line 57, in wrapped_view
    return view_func(*args, **kwargs)
  File "/usr/local/lib/python2.7/dist-packages/rest_framework/views.py", line 400, in dispatch
    response = self.handle_exception(exc)
  File "/usr/local/lib/python2.7/dist-packages/rest_framework/views.py", line 397, in dispatch
    response = handler(request, *args, **kwargs)
  File "./happy365/views.py", line 278, in get
    scores=NLP.sentiment(txt)
UnboundLocalError: local variable 'txt' referenced before assignment
2014-08-05 00:00:41,393 [ERROR] django.request: Internal Server Error: /feed/
Traceback (most recent call last):
  File "/usr/local/lib/python2.7/dist-packages/django/core/handlers/base.py", line 112, in get_response
    response = wrapped_callback(request, *callback_args, **callback_kwargs)
  File "/usr/local/lib/python2.7/dist-packages/django/views/generic/base.py", line 69, in view
    return self.dispatch(request, *args, **kwargs)
  File "/usr/local/lib/python2.7/dist-packages/django/views/decorators/csrf.py", line 57, in wrapped_view
    return view_func(*args, **kwargs)
  File "/usr/local/lib/python2.7/dist-packages/rest_framework/views.py", line 400, in dispatch
    response = self.handle_exception(exc)
  File "/usr/local/lib/python2.7/dist-packages/rest_framework/views.py", line 397, in dispatch
    response = handler(request, *args, **kwargs)
  File "./happy365/views.py", line 278, in get
    scores=NLP.sentiment(txt)
UnboundLocalError: local variable 'txt' referenced before assignment
2014-08-05 02:08:04,085 [WARNING] django.request: Not Found: /
2014-08-05 02:16:50,242 [WARNING] django.request: Not Found: /
2014-08-05 03:17:47,508 [WARNING] django.request: Not Found: /
2014-08-05 03:38:37,470 [WARNING] django.request: Not Found: /
2014-08-05 05:01:01,868 [WARNING] django.request: Not Found: /
2014-08-05 05:15:18,330 [WARNING] django.request: Not Found: /
2014-08-05 05:20:26,777 [WARNING] django.request: Not Found: /
2014-08-05 05:22:22,022 [WARNING] django.request: Not Found: /
2014-08-05 07:32:02,416 [WARNING] django.request: Not Found: /
2014-08-05 07:44:22,363 [WARNING] django.request: Not Found: /
2014-08-05 08:30:52,314 [WARNING] django.request: Not Found: /
2014-08-05 08:51:29,500 [WARNING] django.request: Not Found: /
2014-08-05 09:06:35,795 [ERROR] django.request: Internal Server Error: /feed/
Traceback (most recent call last):
  File "/usr/local/lib/python2.7/dist-packages/django/core/handlers/base.py", line 112, in get_response
    response = wrapped_callback(request, *callback_args, **callback_kwargs)
  File "/usr/local/lib/python2.7/dist-packages/django/views/generic/base.py", line 69, in view
    return self.dispatch(request, *args, **kwargs)
  File "/usr/local/lib/python2.7/dist-packages/django/views/decorators/csrf.py", line 57, in wrapped_view
    return view_func(*args, **kwargs)
  File "/usr/local/lib/python2.7/dist-packages/rest_framework/views.py", line 400, in dispatch
    response = self.handle_exception(exc)
  File "/usr/local/lib/python2.7/dist-packages/rest_framework/views.py", line 397, in dispatch
    response = handler(request, *args, **kwargs)
  File "./happy365/views.py", line 278, in get
    scores=NLP.sentiment(txt)
UnboundLocalError: local variable 'txt' referenced before assignment
2014-08-05 09:20:56,986 [WARNING] django.request: Not Found: /
2014-08-05 09:55:43,525 [WARNING] django.request: Not Found: /
2014-08-05 10:25:28,518 [WARNING] django.request: Not Found: /
2014-08-05 10:26:53,340 [WARNING] django.request: Not Found: /favicon.ico
2014-08-05 10:39:45,835 [ERROR] django.request: Internal Server Error: /feed/
Traceback (most recent call last):
  File "/usr/local/lib/python2.7/dist-packages/django/core/handlers/base.py", line 112, in get_response
    response = wrapped_callback(request, *callback_args, **callback_kwargs)
  File "/usr/local/lib/python2.7/dist-packages/django/views/generic/base.py", line 69, in view
    return self.dispatch(request, *args, **kwargs)
  File "/usr/local/lib/python2.7/dist-packages/django/views/decorators/csrf.py", line 57, in wrapped_view
    return view_func(*args, **kwargs)
  File "/usr/local/lib/python2.7/dist-packages/rest_framework/views.py", line 400, in dispatch
    response = self.handle_exception(exc)
  File "/usr/local/lib/python2.7/dist-packages/rest_framework/views.py", line 397, in dispatch
    response = handler(request, *args, **kwargs)
  File "./happy365/views.py", line 278, in get
    scores=NLP.sentiment(txt)
UnboundLocalError: local variable 'txt' referenced before assignment
2014-08-05 11:24:22,217 [WARNING] django.request: Not Found: /
2014-08-05 12:16:53,461 [WARNING] django.request: Not Found: /
2014-08-05 12:19:30,241 [WARNING] django.request: Not Found: /
2014-08-05 12:24:33,577 [WARNING] django.request: Not Found: /
2014-08-05 12:43:58,759 [WARNING] django.request: Not Found: /
2014-08-05 12:50:17,351 [WARNING] django.request: Not Found: /web-console/ServerInfo.jsp
2014-08-05 12:56:39,399 [WARNING] django.request: Not Found: /
2014-08-05 13:00:55,097 [ERROR] django.request: Internal Server Error: /feed/
Traceback (most recent call last):
  File "/usr/local/lib/python2.7/dist-packages/django/core/handlers/base.py", line 112, in get_response
    response = wrapped_callback(request, *callback_args, **callback_kwargs)
  File "/usr/local/lib/python2.7/dist-packages/django/views/generic/base.py", line 69, in view
    return self.dispatch(request, *args, **kwargs)
  File "/usr/local/lib/python2.7/dist-packages/django/views/decorators/csrf.py", line 57, in wrapped_view
    return view_func(*args, **kwargs)
  File "/usr/local/lib/python2.7/dist-packages/rest_framework/views.py", line 400, in dispatch
    response = self.handle_exception(exc)
  File "/usr/local/lib/python2.7/dist-packages/rest_framework/views.py", line 397, in dispatch
    response = handler(request, *args, **kwargs)
  File "./happy365/views.py", line 278, in get
    scores=NLP.sentiment(txt)
UnboundLocalError: local variable 'txt' referenced before assignment
2014-08-05 13:29:45,671 [WARNING] django.request: Not Found: /
2014-08-05 15:23:21,149 [WARNING] django.request: Not Found: /
2014-08-05 15:30:44,973 [WARNING] django.request: Not Found: /
2014-08-05 15:33:48,416 [WARNING] django.request: Not Found: /
2014-08-05 15:42:45,892 [WARNING] django.request: Not Found: /
2014-08-05 16:21:37,279 [ERROR] django.request: Internal Server Error: /feed/
Traceback (most recent call last):
  File "/usr/local/lib/python2.7/dist-packages/django/core/handlers/base.py", line 112, in get_response
    response = wrapped_callback(request, *callback_args, **callback_kwargs)
  File "/usr/local/lib/python2.7/dist-packages/django/views/generic/base.py", line 69, in view
    return self.dispatch(request, *args, **kwargs)
  File "/usr/local/lib/python2.7/dist-packages/django/views/decorators/csrf.py", line 57, in wrapped_view
    return view_func(*args, **kwargs)
  File "/usr/local/lib/python2.7/dist-packages/rest_framework/views.py", line 400, in dispatch
    response = self.handle_exception(exc)
  File "/usr/local/lib/python2.7/dist-packages/rest_framework/views.py", line 397, in dispatch
    response = handler(request, *args, **kwargs)
  File "./happy365/views.py", line 278, in get
    scores=NLP.sentiment(txt)
UnboundLocalError: local variable 'txt' referenced before assignment
2014-08-06 10:54:05,733 [WARNING] django.request: Not Found: /
2014-08-06 12:14:17,565 [WARNING] django.request: Not Found: /
2014-08-06 12:59:43,614 [WARNING] django.request: Not Found: /
2014-08-06 13:01:31,079 [WARNING] django.request: Not Found: /
